[2019-06-26 14:39:38] INFO [django.channels.server.log_action:141] HTTP GET / 200 [0.15, 127.0.0.1:12544]
[2019-06-26 14:39:39] INFO [django.channels.server.log_action:141] HTTP POST /ulocation 200 [0.00, 127.0.0.1:12544]
[2019-06-26 14:39:39] INFO [django.channels.server.log_action:141] HTTP GET /static/favicon.ico 200 [0.03, 127.0.0.1:12544]
[2019-06-26 14:40:04] INFO [django.channels.server.log_action:141] HTTP GET /internships 200 [0.09, 127.0.0.1:12544]
[2019-06-26 14:41:03] ERROR [django.request.handle_uncaught_exception:118] Internal Server Error: /internships
Traceback (most recent call last):
  File "C:\Users\Sam\AppData\Local\Programs\Python\Python37\lib\site-packages\django\core\handlers\exception.py", line 35, in inner
    response = get_response(request)
  File "C:\Users\Sam\AppData\Local\Programs\Python\Python37\lib\site-packages\django\core\handlers\base.py", line 128, in _get_response
    response = self.process_exception_by_middleware(e, request)
  File "C:\Users\Sam\AppData\Local\Programs\Python\Python37\lib\site-packages\django\core\handlers\base.py", line 126, in _get_response
    response = wrapped_callback(request, *callback_args, **callback_kwargs)
  File "E:\Documents\Web\Linuxjobber\Django\Linuxjobber\home\views.py", line 239, in internships
    for filename, file in request.FILES.iteritems():
AttributeError: 'MultiValueDict' object has no attribute 'iteritems'
[2019-06-26 14:41:03] ERROR [django.channels.server.log_action:154] HTTP POST /internships 500 [0.05, 127.0.0.1:12544]
[2019-06-26 14:41:03] WARNING [django.request.get_response:93] Not Found: /favicon.ico
[2019-06-26 14:41:03] WARNING [django.channels.server.log_action:149] HTTP GET /favicon.ico 404 [0.03, 127.0.0.1:12544]
[2019-06-26 14:42:09] ERROR [django.request.handle_uncaught_exception:118] Internal Server Error: /internships
Traceback (most recent call last):
  File "C:\Users\Sam\AppData\Local\Programs\Python\Python37\lib\site-packages\django\utils\datastructures.py", line 77, in __getitem__
    list_ = super().__getitem__(key)
KeyError: 'file'

During handling of the above exception, another exception occurred:

Traceback (most recent call last):
  File "C:\Users\Sam\AppData\Local\Programs\Python\Python37\lib\site-packages\django\core\handlers\exception.py", line 35, in inner
    response = get_response(request)
  File "C:\Users\Sam\AppData\Local\Programs\Python\Python37\lib\site-packages\django\core\handlers\base.py", line 128, in _get_response
    response = self.process_exception_by_middleware(e, request)
  File "C:\Users\Sam\AppData\Local\Programs\Python\Python37\lib\site-packages\django\core\handlers\base.py", line 126, in _get_response
    response = wrapped_callback(request, *callback_args, **callback_kwargs)
  File "E:\Documents\Web\Linuxjobber\Django\Linuxjobber\home\views.py", line 240, in internships
    if request.FILES['file'].size > MAX_UPLOAD_SIZE:
  File "C:\Users\Sam\AppData\Local\Programs\Python\Python37\lib\site-packages\django\utils\datastructures.py", line 79, in __getitem__
    raise MultiValueDictKeyError(key)
django.utils.datastructures.MultiValueDictKeyError: 'file'
[2019-06-26 14:42:09] ERROR [django.channels.server.log_action:154] HTTP POST /internships 500 [0.06, 127.0.0.1:12699]
[2019-06-26 14:42:38] ERROR [django.request.handle_uncaught_exception:118] Internal Server Error: /internships
Traceback (most recent call last):
  File "C:\Users\Sam\AppData\Local\Programs\Python\Python37\lib\site-packages\django\utils\datastructures.py", line 77, in __getitem__
    list_ = super().__getitem__(key)
KeyError: 'File'

During handling of the above exception, another exception occurred:

Traceback (most recent call last):
  File "C:\Users\Sam\AppData\Local\Programs\Python\Python37\lib\site-packages\django\core\handlers\exception.py", line 35, in inner
    response = get_response(request)
  File "C:\Users\Sam\AppData\Local\Programs\Python\Python37\lib\site-packages\django\core\handlers\base.py", line 128, in _get_response
    response = self.process_exception_by_middleware(e, request)
  File "C:\Users\Sam\AppData\Local\Programs\Python\Python37\lib\site-packages\django\core\handlers\base.py", line 126, in _get_response
    response = wrapped_callback(request, *callback_args, **callback_kwargs)
  File "E:\Documents\Web\Linuxjobber\Django\Linuxjobber\home\views.py", line 240, in internships
    if request.FILES['File'].size > MAX_UPLOAD_SIZE:
  File "C:\Users\Sam\AppData\Local\Programs\Python\Python37\lib\site-packages\django\utils\datastructures.py", line 79, in __getitem__
    raise MultiValueDictKeyError(key)
django.utils.datastructures.MultiValueDictKeyError: 'File'
[2019-06-26 14:42:38] ERROR [django.channels.server.log_action:154] HTTP POST /internships 500 [0.06, 127.0.0.1:12736]
[2019-06-26 14:43:30] ERROR [django.request.handle_uncaught_exception:118] Internal Server Error: /internships
Traceback (most recent call last):
  File "C:\Users\Sam\AppData\Local\Programs\Python\Python37\lib\site-packages\django\core\handlers\exception.py", line 35, in inner
    response = get_response(request)
  File "C:\Users\Sam\AppData\Local\Programs\Python\Python37\lib\site-packages\django\core\handlers\base.py", line 128, in _get_response
    response = self.process_exception_by_middleware(e, request)
  File "C:\Users\Sam\AppData\Local\Programs\Python\Python37\lib\site-packages\django\core\handlers\base.py", line 126, in _get_response
    response = wrapped_callback(request, *callback_args, **callback_kwargs)
  File "E:\Documents\Web\Linuxjobber\Django\Linuxjobber\home\views.py", line 240, in internships
    if request.FILES.size > MAX_UPLOAD_SIZE:
AttributeError: 'MultiValueDict' object has no attribute 'size'
[2019-06-26 14:43:31] ERROR [django.channels.server.log_action:154] HTTP POST /internships 500 [0.06, 127.0.0.1:12790]
[2019-06-26 14:44:15] ERROR [django.request.handle_uncaught_exception:118] Internal Server Error: /internships
Traceback (most recent call last):
  File "C:\Users\Sam\AppData\Local\Programs\Python\Python37\lib\site-packages\django\utils\datastructures.py", line 77, in __getitem__
    list_ = super().__getitem__(key)
KeyError: 'file'

During handling of the above exception, another exception occurred:

Traceback (most recent call last):
  File "C:\Users\Sam\AppData\Local\Programs\Python\Python37\lib\site-packages\django\core\handlers\exception.py", line 35, in inner
    response = get_response(request)
  File "C:\Users\Sam\AppData\Local\Programs\Python\Python37\lib\site-packages\django\core\handlers\base.py", line 128, in _get_response
    response = self.process_exception_by_middleware(e, request)
  File "C:\Users\Sam\AppData\Local\Programs\Python\Python37\lib\site-packages\django\core\handlers\base.py", line 126, in _get_response
    response = wrapped_callback(request, *callback_args, **callback_kwargs)
  File "E:\Documents\Web\Linuxjobber\Django\Linuxjobber\home\views.py", line 240, in internships
    if request.FILES['file']._size > MAX_UPLOAD_SIZE:
  File "C:\Users\Sam\AppData\Local\Programs\Python\Python37\lib\site-packages\django\utils\datastructures.py", line 79, in __getitem__
    raise MultiValueDictKeyError(key)
django.utils.datastructures.MultiValueDictKeyError: 'file'
[2019-06-26 14:44:15] ERROR [django.channels.server.log_action:154] HTTP POST /internships 500 [0.09, 127.0.0.1:12858]
[2019-06-26 14:49:38] ERROR [django.request.handle_uncaught_exception:118] Internal Server Error: /internships
Traceback (most recent call last):
  File "C:\Users\Sam\AppData\Local\Programs\Python\Python37\lib\site-packages\django\core\handlers\exception.py", line 35, in inner
    response = get_response(request)
  File "C:\Users\Sam\AppData\Local\Programs\Python\Python37\lib\site-packages\django\core\handlers\base.py", line 128, in _get_response
    response = self.process_exception_by_middleware(e, request)
  File "C:\Users\Sam\AppData\Local\Programs\Python\Python37\lib\site-packages\django\core\handlers\base.py", line 126, in _get_response
    response = wrapped_callback(request, *callback_args, **callback_kwargs)
  File "E:\Documents\Web\Linuxjobber\Django\Linuxjobber\home\views.py", line 240, in internships
    if request.FILES._size > MAX_UPLOAD_SIZE:
AttributeError: 'MultiValueDict' object has no attribute '_size'
[2019-06-26 14:49:38] ERROR [django.channels.server.log_action:154] HTTP POST /internships 500 [0.06, 127.0.0.1:13154]
[2019-06-26 14:50:08] INFO [django.channels.server.log_action:141] HTTP POST /internships 200 [7.94, 127.0.0.1:13184]
